<!DOCTYPE html>
<html>
<head>
	<title>Chaining</title>
	<link rel="stylesheet" type="text/css" href="../../Assets/bulma.css">
	<link rel="stylesheet" type="text/css" href="../../Assets/Style.css">
	<script type="text/javascript" src="../../Assets/prism.min.js"></script>
	<script type="text/javascript" src="../../Assets/jquery.min.js"></script>
  <link rel="stylesheet" href="../../Assets/prism-dark.css">
</head>
<body class="Body">
<div class="Content Card">






<h1>Chaining</h1>
<p>Let’s return to the problem mentioned in the chapter Introduction: callbacks. If we implement this example using Promise chaining, it would look like this:</p>
<pre>
new Promise(function(resolve, reject) {

  setTimeout(() => resolve(1), 1000); // (*)

}).then(function(result) { // (**)

  alert(result); // 1
  return result * 2;

}).then(function(result) { // (***)

  alert(result); // 2
  return result * 2;

}).then(function(result) {

  alert(result); // 4
  return result * 2;

});
</pre>
<p>The idea is that the result is passed through the chain of <code>.then</code> handlers. The whole thing works, because a call to <code>promise.then</code> returns a promise, so that we can call the next <code>.then</code> on it.</p>
<p>When a handler returns a value, it becomes the result of that promise, so the next <code>.then</code> is called with that value. To make these words more clear, here’s the start of the chain:</p>
<pre>
new Promise(function(resolve, reject) {

  setTimeout(() => resolve(1), 1000);

}).then(function(result) {

  alert(result);
  return result * 2; // <-- (1)

}) // <-- (2)
// .then…
</pre>
<p>The value returned by <code>.then…</code> is a promise, that’s why we are able to add another <code>.then</code> at (2). When the value is returned in (1), that promise becomes resolved, so the next handler runs with the value.</p>
<p>Unlike the chaining, technically we can also add many <code>.then</code> to a single promise, like this:</p>
<pre>
let promise = new Promise(function(resolve, reject) {
  setTimeout(() => resolve(1), 1000);
});

promise.then(function(result) {
  alert(result); // 1
  return result * 2;
});

promise.then(function(result) {
  alert(result); // 1
  return result * 2;
});

promise.then(function(result) {
  alert(result); // 1
  return result * 2;
});
</pre>
<p>…But that’s a totally different thing. Here’s the picture (compare it with the chaining above):</p>
<img src="../Assets/img/promise-then-many.png">
<p>All <code>.then</code> on the same promise get the same result – the result of that promise. So in the code above all alert show the same: <code>1</code>. There is no result-passing between them.</p>
<p>In practice we rarely need multiple handlers for one promise. Chaining is used much more often.</p>















<h1>Returning promises</h1>
<p>Normally, a value returned by a <code>.then</code> handler is immediately passed to the next handler. But there’s an exception. If the returned value is a promise, then the further execution is suspended until it settles. After that, the result of that promise is given to the next <code>.then</code> handler.</p>
<pre>
new Promise(function(resolve, reject) {

  setTimeout(() => resolve(1), 1000);

}).then(function(result) {

  alert(result); // 1

  return new Promise((resolve, reject) => { // (*)
    setTimeout(() => resolve(result * 2), 1000);
  });

}).then(function(result) { // (**)

  alert(result); // 2

  return new Promise((resolve, reject) => {
    setTimeout(() => resolve(result * 2), 1000);
  });

}).then(function(result) {

  alert(result); // 4

});
</pre>
<p>Here the first <code>.then</code> shows <code>1</code> returns <code>new Promise(…)</code> in the line <code>(*)</code>. After one second it resolves, and the result (the argument of resolve, here it’s <code>result*2</code>) is passed on to handler of the second <code>.then</code> in the line <code>(**)</code>. It shows <code>2</code> and does the same thing.</p>
<p>So the output is again <code>1 → 2 → 4</code>, but now with <code>1</code> second delay between <code>alert</code> calls.</p>
<p>Returning promises allows us to build chains of asynchronous actions.</p>










<h1>Example: loadScript</h1>
<p>Let’s use this feature with <code>loadScript</code> to load scripts one by one, in sequence:</p>
<pre>
loadScript("/article/promise-chaining/one.js").then(function(script) {
    return loadScript("/article/promise-chaining/two.js");
  }).then(function(script) {
    return loadScript("/article/promise-chaining/three.js");
  }).then(function(script) {
    // use functions declared in scripts
    // to show that they indeed loaded
    one();
    two();
    three();
  });
</pre>
<p>Here each <code>loadScript</code> call returns a promise, and the next <code>.then</code> runs when it resolves. Then it initiates the loading of the next script. So scripts are loaded one after another. We can add more asynchronous actions to the chain. Please note that code is still “flat”, it grows down, not to the right. There are no signs of “pyramid of doom”.</p>
<p>Please note that technically it is also possible to write .then directly after each promise, without returning them, like this:</p>
<pre>
loadScript("/article/promise-chaining/one.js").then(function(script1) {
  loadScript("/article/promise-chaining/two.js").then(function(script2) {
    loadScript("/article/promise-chaining/three.js").then(function(script3) {
      // this function has access to variables script1, script2 and script3
      one();
      two();
      three();
    });
  });
});
</pre>
<p>This code does the same: loads 3 scripts in sequence. But it “grows to the right”. So we have the same problem as with callbacks. Use chaining (return promises from <code>.then</code>) to evade it.</p>
<p>Sometimes it’s ok to write <code>.then</code> directly, because the nested function has access to the outer scope (here the most nested callback has access to all variables scriptX), but that’s an exception rather than a rule.</p>








<h1>Thenables</h1>
<p>To be precise, .then may return an arbitrary “thenable” object, and it will be treated the same way as a promise. A “thenable” object is any object with a method <code>.then</code>.</p>
<p>The idea is that 3rd-party libraries may implement “promise-compatible” objects of their own. They can have extended set of methods, but also be compatible with native promises, because they implement <code>.then</code>.</p>
<p>Here is an example of thenable object:</p>
<pre>
class Thenable {
  constructor(num) {
    this.num = num;
  }
  then(resolve, reject) {
    alert(resolve); // function() { native code }
    // resolve with this.num*2 after the 1 second
    setTimeout(() => resolve(this.num * 2), 1000); // (**)
  }
}

new Promise(resolve => resolve(1))
  .then(result => {
    return new Thenable(result); // (*)
  })
  .then(alert); // shows 2 after 1000ms
</pre>
<p>JavaScript checks the object returned by <code>.then</code> handler in the line <code>(*)</code>: if it has a callable method named <code>then</code>, then it calls that method providing native functions resolve, reject as arguments (similar to executor) and waits until one of them is called. In the example above <code>resolve(2)</code> is called after <code>1</code> second <code>(**)</code>. Then the result is passed further down the chain.</p>
<p>This feature allows to integrate custom objects with promise chains without having to inherit from Promise.</p>










<h1>Implicit try…catch</h1>
<p>The code of the executor and promise handlers has an "invisible try..catch" around it. If an error happens, it gets caught and treated as a rejection. For instance, this code:</p>
<pre>
new Promise(function(resolve, reject) {
  throw new Error("Whoops!");
}).catch(alert); // Error: Whoops!
</pre>
<p>…Works the same way as this:</p>
<pre>
new Promise(function(resolve, reject) {
  reject(new Error("Whoops!"));
}).catch(alert); // Error: Whoops!
</pre>
<p>The "invisible try..catch" around the executor automatically catches the error and treats it as a rejection. That’s so not only in the executor, but in handlers as well. If we throw inside <code>.then</code> handler, that means a rejected promise, so the control jumps to the nearest error handler. Here’s an example:</p>
<pre>
new Promise(function(resolve, reject) {
  resolve("ok");
}).then(function(result) {
  throw new Error("Whoops!"); // rejects the promise
}).catch(alert); // Error: Whoops!
</pre>
<p>That’s so not only for <code>throw</code>, but for any errors, including programming errors as well:</p>
<pre>
new Promise(function(resolve, reject) {
  resolve("ok");
}).then(function(result) {
  blabla(); // no such function
}).catch(alert); // ReferenceError: blabla is not defined
</pre>
<p>As a side effect, the final <code>.catch</code> not only catches explicit rejections, but also occasional errors in the handlers above.</p>












<h1>Rethrowing</h1>
<p>As we already noticed, <code>.catch</code> behaves like <code>try..catch</code>. We may have as many <code>.then</code> as we want, and then use a single <code>.catch</code> at the end to handle errors in all of them.</p>
<p>In a regular <code>try..catch</code> we can analyze the error and maybe <code>rethrow</code> it if can’t handle. The same thing is possible for promises. If we throw inside <code>.catch</code>, then the control goes to the next closest error handler. And if we handle the error and finish normally, then it continues to the closest successful <code>.then</code> handler.</p>
<p>In the example below the <code>.catch</code> successfully handles the error:</p>
<pre>
// the execution: catch -> then
new Promise(function(resolve, reject) {

  throw new Error("Whoops!");

}).catch(function(error) {

  alert("The error is handled, continue normally");

}).then(() => alert("Next successful handler runs"));
</pre>
<p>Here the .catch block finishes normally. So the next successful handler is called. Or it could return something, that would be the same.</p>
<p>…And here the <code>.catch</code> block analyzes the error and throws it again:</p>
<pre>
// the execution: catch -> catch -> then
new Promise(function(resolve, reject) {

  throw new Error("Whoops!");

}).catch(function(error) { // (*)

  if (error instanceof URIError) {
    // handle it
  } else {
    alert("Can't handle such error");

    throw error; // throwing this or another error jumps to the next catch
  }

}).then(function() {
  /* never runs here */
}).catch(error => { // (**)

  alert(`The unknown error has occurred: ${error}`);
  // don't return anything => execution goes the normal way

});
</pre>
<p>The handler (*) catches the error and just can’t handle it, because it’s not <code>URIError</code>, so it throws it again. Then the execution jumps to the next <code>.catch</code> down the chain <code>(**)</code>.</p>








<h1>Unhandled rejections</h1>
<p>What happens when an error is not handled? For instance, after the <code>rethrow</code> as in the example above. Or if we forget to append an error handler to the end of the chain, like here:</p>
<pre>
new Promise(function() {
  noSuchFunction(); // Error here (no such function)
}); // no .catch attached
</pre>
<p>Or here:</p>
<pre>
// a chain of promises without .catch at the end
new Promise(function() {
  throw new Error("Whoops!");
}).then(function() {
  // ...something...
}).then(function() {
  // ...something else...
}).then(function() {
  // ...but no catch after it!
});
</pre>
<p>In case of an error, the promise state becomes “rejected”, and the execution should jump to the closest rejection handler. But there is no such handler in the examples above. So the error gets “stuck”. In practice, that’s usually because of the bad code. Indeed, how come there’s no error handling?</p>
<p>Most JavaScript engines track such situations and generate a global error in that case. We can see it in the console. In the browser we can catch it using the event <code>unhandledrejection</code>:</p>
<pre>
window.addEventListener('unhandledrejection', function(event) {
  // the event object has two special properties:
  alert(event.promise); // [object Promise] - the promise that generated the error
  alert(event.reason); // Error: Whoops! - the unhandled error object
});

new Promise(function() {
  throw new Error("Whoops!");
}); // no catch to handle the error
</pre>
<p>The event is the part of the HTML standard. Now if an error occurs, and there’s no <code>.catch</code>, the <code>unhandledrejection</code> handler triggers: the <code>event</code> object has the information about the error, so we can do something with it.</p>
<p>Usually such errors are unrecoverable, so our best way out is to inform the user about the problem and probably report about the incident to the server.</p>
<p>In non-browser environments like Node.JS there are other similar ways to track unhandled errors.</p>

























</div>
</body>
</html>